<?xml version="1.0"?>
<robot name="car_with_steering_suspension">

  <!-- ðŸš— ì°¨ì²´ -->
  <link name="car_body">
    <inertial>
      <mass value="1200.0"/>
      <inertia
        ixx="400" ixy="0"  ixz="0"
        iyy="800" iyz="0"
        izz="400"/>
    </inertial>
    <collision>
      <geometry><box size="2.5 1.2 0.5"/></geometry>
    </collision>
    <visual>
      <origin xyz="0 0 -0.636" rpy="0 0 0"/>
      <geometry>
        <mesh filename="car_parts/car_body.dae"/>
      </geometry>
    </visual>
  </link>

  <!-- ðŸ›ž ë°”í€´ ë§í¬ -->
  <link name="wheel_fl">
    <inertial>
      <mass value="20.0"/>
      <inertia
        ixx="0.5" ixy="0" ixz="0"
        iyy="1.0" iyz="0"
        izz="0.5"/>
    </inertial>
    <collision>
      <origin rpy="1.5708 0 0"/>
      <geometry><cylinder radius="0.35" length="0.2"/></geometry>
    </collision>
    <visual>
      <origin xyz="1.130 0.740 -0.544" rpy="1.5708 0 -1.5708"/>
      <geometry>
        <mesh filename="car_parts/wheel_fl.dae"/>
      </geometry>
    </visual>
  </link>

  <link name="wheel_fr">
    <inertial>
      <mass value="20.0"/>
      <inertia
        ixx="0.5" ixy="0" ixz="0"
        iyy="1.0" iyz="0"
        izz="0.5"/>
    </inertial>
    <collision>
      <origin rpy="1.5708 0 0"/>
      <geometry><cylinder radius="0.35" length="0.2"/></geometry>
    </collision>
    <visual>
      <origin xyz="1.130 -0.740 -0.544" rpy="1.5708 0 -1.5708"/>
      <geometry>
        <mesh filename="car_parts/wheel_fr.dae"/>
      </geometry>
    </visual>
  </link>

  <link name="wheel_rl">
    <inertial>
      <mass value="20.0"/>
      <inertia
        ixx="0.5" ixy="0" ixz="0"
        iyy="1.0" iyz="0"
        izz="0.5"/>
    </inertial>
    <collision>
      <origin rpy="1.5708 0 0"/>
      <geometry><cylinder radius="0.35" length="0.2"/></geometry>
    </collision>
    <visual>
      <origin xyz="-1.000 0.740 -0.544" rpy="1.5708 0 -1.5708"/>
      <geometry>
        <mesh filename="car_parts/wheel_rl.dae"/>
      </geometry>
    </visual>
  </link>

  <link name="wheel_rr">
    <inertial>
      <mass value="20.0"/>
      <inertia
        ixx="0.5" ixy="0" ixz="0"
        iyy="1.0" iyz="0"
        izz="0.5"/>
    </inertial>
    <collision>
      <origin rpy="1.5708 0 0"/>
      <geometry><cylinder radius="0.35" length="0.2"/></geometry>
    </collision>
    <visual>
      <origin xyz="-1.000 -0.740 -0.544" rpy="1.5708 0 -1.5708"/>
      <geometry>
        <mesh filename="car_parts/wheel_rr.dae"/>
      </geometry>
    </visual>
  </link>

  <!-- âš™ï¸ ì„œìŠ¤íŽœì…˜ ë§í¬ (fixed ì¡°ì¸íŠ¸ì´ë¯€ë¡œ ìµœì†Œí•œì˜ ì§ˆëŸ‰) -->
  <link name="susp_fl">
    <inertial>
      <mass value="1.0"/>
      <inertia ixx="0.01" ixy="0" ixz="0" iyy="0.01" iyz="0" izz="0.01"/>
    </inertial>
  </link>
  <link name="susp_fr">
    <inertial>
      <mass value="1.0"/>
      <inertia ixx="0.01" ixy="0" ixz="0" iyy="0.01" iyz="0" izz="0.01"/>
    </inertial>
  </link>
  <link name="susp_rl">
    <inertial>
      <mass value="1.0"/>
      <inertia ixx="0.01" ixy="0" ixz="0" iyy="0.01" iyz="0" izz="0.01"/>
    </inertial>
  </link>
  <link name="susp_rr">
    <inertial>
      <mass value="1.0"/>
      <inertia ixx="0.01" ixy="0" ixz="0" iyy="0.01" iyz="0" izz="0.01"/>
    </inertial>
  </link>

  <!-- ðŸ”„ ì¡°í–¥ ë§í¬ (ì•žë°”í€´ìš©, ì¡°í–¥ê³¼ íšŒì „ì„ ë¶„ë¦¬) -->
  <link name="steer_fl_link">
    <inertial>
      <mass value="0.5"/>
      <inertia ixx="0.01" ixy="0" ixz="0" iyy="0.01" iyz="0" izz="0.01"/>
    </inertial>
  </link>
  <link name="steer_fr_link">
    <inertial>
      <mass value="0.5"/>
      <inertia ixx="0.01" ixy="0" ixz="0" iyy="0.01" iyz="0" izz="0.01"/>
    </inertial>
  </link>

  <!-- ðŸ”© ì¡°ì¸íŠ¸ êµ¬ì¡° -->
  <!-- ì•žì™¼ìª½ -->
  <joint name="susp_fl_joint" type="fixed">
    <parent link="car_body"/>
    <child link="susp_fl"/>
    <origin xyz="1.2 -0.6 -0.25" rpy="0 0 0"/>
  </joint>

  <joint name="steer_fl" type="revolute">
    <parent link="susp_fl"/>
    <child link="steer_fl_link"/>
    <origin xyz="0 0 -0.35" rpy="0 0 0"/>
    <axis xyz="0 0 1"/>
    <limit lower="-0.6" upper="0.6" effort="500" velocity="2"/>
  </joint>

  <joint name="wheel_fl_rotate" type="continuous">
    <parent link="steer_fl_link"/>
    <child link="wheel_fl"/>
    <origin xyz="0 0 0" rpy="0 0 0"/>
    <axis xyz="0 1 0"/>
  </joint>

  <!-- ì•žì˜¤ë¥¸ìª½ -->
  <joint name="susp_fr_joint" type="fixed">
    <parent link="car_body"/>
    <child link="susp_fr"/>
    <origin xyz="1.2 0.6 -0.25" rpy="0 0 0"/>
  </joint>

  <joint name="steer_fr" type="revolute">
    <parent link="susp_fr"/>
    <child link="steer_fr_link"/>
    <origin xyz="0 0 -0.35" rpy="0 0 0"/>
    <axis xyz="0 0 1"/>
    <limit lower="-0.6" upper="0.6" effort="500" velocity="2"/>
  </joint>

  <joint name="wheel_fr_rotate" type="continuous">
    <parent link="steer_fr_link"/>
    <child link="wheel_fr"/>
    <origin xyz="0 0 0" rpy="0 0 0"/>
    <axis xyz="0 1 0"/>
  </joint>

  <!-- ë’¤ì™¼ìª½ -->
  <joint name="susp_rl_joint" type="fixed">
    <parent link="car_body"/>
    <child link="susp_rl"/>
    <origin xyz="-1.2 -0.6 -0.25" rpy="0 0 0"/>
  </joint>

  <joint name="rear_rl" type="continuous">
    <parent link="susp_rl"/>
    <child link="wheel_rl"/>
    <origin xyz="0 0 -0.35" rpy="0 0 0"/>
    <axis xyz="0 1 0"/>
  </joint>

  <!-- ë’¤ì˜¤ë¥¸ìª½ -->
  <joint name="susp_rr_joint" type="fixed">
    <parent link="car_body"/>
    <child link="susp_rr"/>
    <origin xyz="-1.2 0.6 -0.25" rpy="0 0 0"/>
  </joint>

  <joint name="rear_rr" type="continuous">
    <parent link="susp_rr"/>
    <child link="wheel_rr"/>
    <origin xyz="0 0 -0.35" rpy="0 0 0"/>
    <axis xyz="0 1 0"/>
  </joint>

</robot>
